Workbook

Sheet Space technology manufacturers
A1: Company | B1: Country | C1: Revenue 2021 (in milion $) | D1: Revenue 2022 (in milion $) | E1: #Shareholders | F1: Share of non-EU direct ownership | G1: Share of non-EU indirect ownership | H1: Weighted share of non-EU direct industry ownership | I1: Weighted share of non-EU indirect industry ownership | J1: US direct ownership | K1: US indirect ownership | L1: Canada direct ownership | M1: Canada indirect ownership | N1: UK direct ownership | O1: UK indirect ownership | P1: Switzerland direct ownership | Q1: Switzerland direct ownership | R1: Norway direct ownership | S1: Norway indirect ownership | T1: US direct share | U1: US indirect share | V1: Canada direct share | W1: Canada indirect share | X1: UK direct share | Y1: UK indirect share | Z1: Switzerland direct share | AA1: Switzerland indirect share | AB1: Norway direct share | AC1: Norway indirect share | AD1: Owned by | AE1: Country owner | AF1: Revenu owner 2021 (in milion $) | AG1: #Shareholders owner
A2: Aerospacelab | B2: BE | E2: 7
A3: Air Liquide Advanced Technologies | B3: FR | C3: 306.2 | E3: 2 | F3: =Ownership!D235/Ownership!D236 -> 0.052329824 | G3: =Ownership!E235/Ownership!E236 -> 0.73739148 | H3: =F3*C3 -> 16.023392 | I3: =G3*C3 -> 225.78927 | J3: =(Ownership!D184)/Ownership!D236 -> 0.052329824 | K3: =Ownership!E230/Ownership!E236 -> 0.49179961 | L3: =Ownership!D231/Ownership!D236 -> 0 | M3: =Ownership!E231/Ownership!E236 -> 0.062247944 | N3: =Ownership!D232/Ownership!D236 -> 0 | O3: =Ownership!E232/Ownership!E236 -> 0.017507234 | P3: =Ownership!D233/Ownership!D236 -> 0 | Q3: =Ownership!E233/Ownership!E236 -> 0.031123972 | R3: =Ownership!D234/Ownership!D236 -> 0 | S3: =Ownership!E234/Ownership!E236 -> 0.094020333 | T3: =J3*C3 -> 16.023392 | U3: =K3*C3 -> 150.58904 | V3: =L3*C3 -> 0 | W3: =M3*C3 -> 19.060321 | X3: =N3*C3 -> 0 | Y3: =O3*C3 -> 5.3607152 | Z3: =P3*C3 -> 0 | AA3: =Q3*C3 -> 9.5301603 | AB3: =R3*C3 -> 0 | AC3: =S3*C3 -> 28.789026 | AD3: L'AIR LIQUIDE SOCIETE ANONYME POUR L'ETUDE ET L'EXPLOITATION DES PROCEDES GEORGES CLAUDE | AE3: FR | AF3: 32468 | AG3: 49
A4: Air Liquide France Industry | B4: FR | D4: 1773.2 | E4: 2 | F4: =Ownership!D235/Ownership!D236 -> 0.052329824 | G4: =Ownership!E235/Ownership!E236 -> 0.73739148 | H4: =F4*D4 -> 92.791244 | I4: =G4*D4 -> 1307.5426 | J4: =(Ownership!D184)/Ownership!D236 -> 0.052329824 | K4: =Ownership!E230/Ownership!E236 -> 0.49179961 | L4: =Ownership!D231/Ownership!D236 -> 0 | M4: =Ownership!E231/Ownership!E236 -> 0.062247944 | N4: =Ownership!D232/Ownership!D236 -> 0 | O4: =Ownership!E232/Ownership!E236 -> 0.017507234 | P4: =Ownership!D233/Ownership!D236 -> 0 | Q4: =Ownership!E233/Ownership!E236 -> 0.031123972 | R4: =Ownership!D234/Ownership!D236 -> 0 | S4: =Ownership!E234/Ownership!E236 -> 0.094020333 | T4: =J4*D4 -> 92.791244 | U4: =K4*D4 -> 872.05907 | V4: =L4*D4 -> 0 | W4: =M4*D4 -> 110.37806 | X4: =N4*D4 -> 0 | Y4: =O4*D4 -> 31.043828 | Z4: =P4*D4 -> 0 | AA4: =Q4*D4 -> 55.189028 | AB4: =R4*D4 -> 0 | AC4: =S4*D4 -> 166.71685 | AD4: L'AIR LIQUIDE SOCIETE ANONYME POUR L'ETUDE ET L'EXPLOITATION DES PROCEDES GEORGES CLAUDE | AE4: FR | AF4: 32468 | AG4: 49
A5: Airbus Defence & Space GMBH | B5: DE | C5: 4645.9 | E5: 2 | F5: =Ownership!D110/Ownership!D111 -> 0 | G5: =Ownership!E84/Ownership!E85 -> 0.13841121 | H5: =F5*C5 -> 0 | I5: =G5*C5 -> 643.04466 | J5: =Ownership!D79/Ownership!D85 -> 0.092754528 | K5: =Ownership!E79/Ownership!E85 -> 0.13841121 | L5: =Ownership!D80/Ownership!D85 -> 0 | M5: =Ownership!E80/Ownership!E85 -> 0 | N5: =Ownership!D81/Ownership!D85 -> 0 | O5: =Ownership!E81/Ownership!E85 -> 0 | P5: =Ownership!D82/Ownership!D85 -> 0 | Q5: =Ownership!E82/Ownership!E85 -> 0 | R5: =Ownership!D83/Ownership!D85 -> 0 | S5: =Ownership!E83/Ownership!E85 -> 0 | T5: =J5*C5 -> 430.92826 | U5: =K5*C5 -> 643.04466 | V5: =L5*C5 -> 0 | W5: =M5*C5 -> 0 | X5: =N5*C5 -> 0 | Y5: =O5*C5 -> 0 | Z5: =P5*C5 -> 0 | AA5: =Q5*C5 -> 0 | AB5: =R5*C5 -> 0 | AC5: =S5*C5 -> 0 | AD5: Airbus SE | AE5: NL | AF5: 63179 | AG5: 12
A6: Airbus Defence & Space Netherlands BV | B6: NL | C6: 62.3 | E6: 1 | F6: =Ownership!D110/Ownership!D111 -> 0 | G6: =Ownership!E84/Ownership!E85 -> 0.13841121 | H6: =F6*C6 -> 0 | I6: =G6*C6 -> 8.6230186 | J6: =Ownership!D79/Ownership!D85 -> 0.092754528 | K6: =Ownership!E79/Ownership!E85 -> 0.13841121 | L6: =Ownership!D80/Ownership!D85 -> 0 | M6: =Ownership!E80/Ownership!E85 -> 0 | N6: =Ownership!D81/Ownership!D85 -> 0 | O6: =Ownership!E81/Ownership!E85 -> 0 | P6: =Ownership!E81/Ownership!E85 -> 0 | Q6: =Ownership!E81/Ownership!E85 -> 0 | R6: =Ownership!E81/Ownership!E85 -> 0 | S6: =Ownership!E81/Ownership!E85 -> 0 | T6: =J6*C6 -> 5.7786071 | U6: =K6*C6 -> 8.6230186 | V6: =L6*C6 -> 0 | W6: =M6*C6 -> 0 | X6: =N6*C6 -> 0 | Y6: =O6*C6 -> 0 | Z6: =P6*C6 -> 0 | AA6: =Q6*C6 -> 0 | AB6: =R6*C6 -> 0 | AC6: =S6*C6 -> 0 | AD6: Airbus SE | AE6: NL | AF6: 63179 | AG6: 12
A7: Airbus Defence & Space SA | B7: ES | C7: 3769.6 | E7: 1 | F7: =Ownership!D110/Ownership!D111 -> 0 | G7: =Ownership!E84/Ownership!E85 -> 0.13841121 | H7: =F7*C7 -> 0 | I7: =G7*C7 -> 521.75491 | J7: =Ownership!D79/Ownership!D85 -> 0.092754528 | K7: =Ownership!E79/Ownership!E85 -> 0.13841121 | L7: =Ownership!D80/Ownership!D85 -> 0 | M7: =Ownership!E80/Ownership!E85 -> 0 | N7: =Ownership!D81/Ownership!D85 -> 0 | O7: =Ownership!E81/Ownership!E85 -> 0 | P7: =Ownership!E81/Ownership!E85 -> 0 | Q7: =Ownership!E81/Ownership!E85 -> 0 | R7: =Ownership!E81/Ownership!E85 -> 0 | S7: =Ownership!E81/Ownership!E85 -> 0 | T7: =J7*$C$7 -> 349.64747 | U7: =K7*$C$7 -> 521.75491 | V7: =L7*$C$7 -> 0 | W7: =M7*$C$7 -> 0 | X7: =N7*$C$7 -> 0 | Y7: =O7*$C$7 -> 0 | Z7: =P7*$C$7 -> 0 | AA7: =Q7*$C$7 -> 0 | ... AC7: =S7*$C$7 -> 0 | AD7: Airbus SE | AE7: NL | AF7: 63179 | AG7: 12
A8: Airbus Defence & Space SAS | B8: FR | C8: 3335.7 | E8: 1 | F8: =Ownership!D110/Ownership!D111 -> 0 | G8: =Ownership!E84/Ownership!E85 -> 0.13841121 | H8: =F8*C8 -> 0 | I8: =G8*C8 -> 461.69828 | J8: =Ownership!D79/Ownership!D85 -> 0.092754528 | K8: =Ownership!E79/Ownership!E85 -> 0.13841121 | L8: =Ownership!D80/Ownership!D85 -> 0 | M8: =Ownership!E80/Ownership!E85 -> 0 | N8: =Ownership!D81/Ownership!D85 -> 0 | O8: =Ownership!E81/Ownership!E85 -> 0 | P8: =Ownership!E81/Ownership!E85 -> 0 | Q8: =Ownership!E81/Ownership!E85 -> 0 | R8: =Ownership!E81/Ownership!E85 -> 0 | S8: =Ownership!E81/Ownership!E85 -> 0 | T8: =J8*$C$8 -> 309.40128 | U8: =K8*$C$8 -> 461.69828 | V8: =L8*$C$8 -> 0 | W8: =M8*$C$8 -> 0 | X8: =N8*$C$8 -> 0 | Y8: =O8*$C$8 -> 0 | Z8: =P8*$C$8 -> 0 | AA8: =Q8*$C$8 -> 0 | ... AC8: =S8*$C$8 -> 0 | AD8: Airbus SE | AE8: NL | AF8: 63179 | AG8: 12
A9: ALTEC (Aerospace Logistics Technology Engineering Company) | B9: IT | D9: 23.8 | E9: 3 | F9: =Ownership!D177/Ownership!D178 -> 0 | G9: =Ownership!E177/Ownership!E178 -> 0.20733636 | H9: =F9*D9 -> 0 | I9: =G9*D9 -> 4.9346054 | J9: =Ownership!D172/Ownership!D178 -> 0 | K9: =Ownership!E172/Ownership!E178 -> 0.13822424 | L9: =Ownership!D173/Ownership!D178 -> 0 | M9: =Ownership!E173/Ownership!E178 -> 0.026836089 | N9: =Ownership!D174/Ownership!D178 -> 0 | O9: =Ownership!E174/Ownership!E178 -> 0.011641226 | P9: =Ownership!D175/Ownership!D178 -> 0 | Q9: =Ownership!E175/Ownership!E178 -> 0.0031860197 | R9: =Ownership!D176/Ownership!D178 -> 0 | S9: =Ownership!E176/Ownership!E178 -> 0.019361197 | T9: =J9*$D$9 -> 0 | U9: =K9*$D$9 -> 3.2897369 | V9: =L9*$D$9 -> 0 | W9: =M9*$D$9 -> 0.63869893 | X9: =N9*$D$9 -> 0 | Y9: =O9*$D$9 -> 0.27706118 | Z9: =P9*$D$9 -> 0 | AA9: =Q9*$D$9 -> 0.07582727 | ... AC9: =S9*$D$9 -> 0.46079649 | AD9: Thales | AE9: FR | AF9: 20679.6 | AG9: 57
A10: Alter Technology TUV Nord France | B10: FR | C10: 9.2 | E10: 2 | F10: =Ownership!D250/Ownership!D251 -> 0 | G10: =Ownership!E250/Ownership!E251 -> 0 | H10: =F10*C10 -> 0 | I10: =G10*C10 -> 0 | J10: 0 | K10: 0 | L10: 0 | M10: 0 | N10: 0 | O10: 0 | P10: 0 | Q10: 0 | R10: 0 | S10: 0 | T10: =J10*$C$10 -> 0 | U10: =K10*$C$10 -> 0 | V10: =L10*$C$10 -> 0 | W10: =M10*$C$10 -> 0 | X10: =N10*$C$10 -> 0 | Y10: =O10*$C$10 -> 0 | Z10: =P10*$C$10 -> 0 | AA10: =Q10*$C$10 -> 0 | ... AC10: =S10*$C$10 -> 0 | AD10: TUEV Nord AG | AE10: DE | AF10: 1597.8 | AG10: 3
A11: Alter Technology TUV Nord SA | B11: ES | C11: 46.5 | E11: 1 | F11: =Ownership!D250/Ownership!D251 -> 0 | G11: =Ownership!E250/Ownership!E251 -> 0 | H11: =F11*C11 -> 0 | I11: =G11*C11 -> 0 | J11: 0 | K11: 0 | L11: 0 | M11: 0 | N11: 0 | O11: 0 | P11: 0 | Q11: 0 | R11: 0 | S11: 0 | T11: =J11*$C$11 -> 0 | U11: =K11*$C$11 -> 0 | V11: =L11*$C$11 -> 0 | W11: =M11*$C$11 -> 0 | X11: =N11*$C$11 -> 0 | Y11: =O11*$C$11 -> 0 | Z11: =P11*$C$11 -> 0 | AA11: =Q11*$C$11 -> 0 | ... AC11: =S11*$C$11 -> 0 | AD11: TUEV Nord AG | AE11: DE | AF11: 1597.8 | AG11: 3
A12: Antwerp Space NV | B12: BE | D12: 9.9 | E12: 1 | F12: =Ownership!D110/Ownership!D111 -> 0 | G12: =Ownership!E110/Ownership!E111 -> 0.45922747 | H12: =F12*D12 -> 0 | I12: =G12*D12 -> 4.5463519 | J12: 0 | K12: =Ownership!E105/Ownership!E111 -> 0.15879828 | L12: 0 | M12: =Ownership!E106/Ownership!E111 -> 0 | N12: 0 | O12: =Ownership!E107/Ownership!E111 -> 0.15665236 | P12: 0 | Q12: =Ownership!E108/Ownership!E111 -> 0.14377682 | R12: 0 | S12: =Ownership!E109/Ownership!E111 -> 0 | T12: =J12*$D$12 -> 0 | U12: =K12*$D$12 -> 1.572103 | V12: =L12*$D$12 -> 0 | W12: =M12*$D$12 -> 0 | X12: =N12*$D$12 -> 0 | Y12: =O12*$D$12 -> 1.5508584 | Z12: =P12*$D$12 -> 0 | AA12: =Q12*$D$12 -> 1.4233906 | ... AC12: =S12*$D$12 -> 0 | AD12: OHB SE | AE12: DE | AF12: 1037 | AG12: 18
A13: ArianeGroup GMBH | B13: DE | C13: 326.4 | E13: 1 | F13: =Ownership!D38/Ownership!D39 -> 0 | G13: =Ownership!E38/Ownership!E39 -> 0.13255361 | H13: =F13*C13 -> 0 | I13: =G13*C13 -> 43.265497 | J13: 0 | K13: =Ownership!E33/Ownership!E39 -> 0.043805501 | L13: 0 | M13: =Ownership!E34/Ownership!E39 -> 0 | N13: 0 | O13: =Ownership!E35/Ownership!E39 -> 0.054905783 | P13: 0 | Q13: =Ownership!E36/Ownership!E39 -> 0 | R13: 0 | S13: =Ownership!E37/Ownership!E39 -> 0 | T13: =J13*$C$13 -> 0 | U13: =K13*$C$13 -> 14.298116 | V13: =L13*$C$13 -> 0 | W13: =M13*$C$13 -> 0 | X13: =N13*$C$13 -> 0 | Y13: =O13*$C$13 -> 17.921248 | Z13: =P13*$C$13 -> 0 | AA13: =Q13*$C$13 -> 0 | ... AC13: =S13*$C$13 -> 0 | AD13: ArianeGroup Holding | AE13: FR | AF13: 11.8 | AG13: 2
A14: ArianeGroup SAS | B14: FR | D14: 2243.7 | E14: 1 | F14: =Ownership!D38/Ownership!D39 -> 0 | G14: =Ownership!E38/Ownership!E39 -> 0.13255361 | H14: =F14*D14 -> 0 | I14: =G14*D14 -> 297.41053 | J14: =J13 -> 0 | K14: =K13 -> 0.043805501 | L14: =L13 -> 0 | M14: =M13 -> 0 | N14: =N13 -> 0 | O14: =O13 -> 0.054905783 | P14: =P13 -> 0 | Q14: =Q13 -> 0 | ... S14: =S13 -> 0 | T14: =J14*$D$14 -> 0 | U14: =K14*$D$14 -> 98.286404 | V14: =L14*$D$14 -> 0 | W14: =M14*$D$14 -> 0 | X14: =N14*$D$14 -> 0 | Y14: =O14*$D$14 -> 123.19211 | Z14: =P14*$D$14 -> 0 | AA14: =Q14*$D$14 -> 0 | ... AC14: =S14*$D$14 -> 0 | AD14: ArianeGroup Holding | AE14: FR | AF14: 11.8 | AG14: 2
A15: Arianespace | B15: FR | C15: 1467.8 | E15: 1 | F15: =Ownership!D38/Ownership!D39 -> 0 | G15: =Ownership!E38/Ownership!E39 -> 0.13255361 | H15: =F15*C15 -> 0 | I15: =G15*C15 -> 194.56218 | J15: =J14 -> 0 | K15: =K14 -> 0.043805501 | L15: =L14 -> 0 | M15: =M14 -> 0 | N15: =N14 -> 0 | O15: =O14 -> 0.054905783 | P15: =P14 -> 0 | Q15: =Q14 -> 0 | ... S15: =S14 -> 0 | T15: =J15*$C15 -> 0 | U15: =K15*$C15 -> 64.297715 | V15: =L15*$C15 -> 0 | W15: =M15*$C15 -> 0 | X15: =N15*$C15 -> 0 | Y15: =O15*$C15 -> 80.590708 | Z15: =P15*$C15 -> 0 | AA15: =Q15*$C15 -> 0 | ... AC15: =S15*$C15 -> 0 | AD15: ArianeGroup Holding | AE15: FR | AF15: 11.8 | AG15: 2
A16: Avio SPA | B16: IT | D16: 435.6 | E16: 24 | F16: =Ownership!D310/Ownership!D311 -> 0 | G16: =Ownership!E310/Ownership!E311 -> 0.1270711 | H16: =F16*D16 -> 0 | I16: =G16*D16 -> 55.352171 | J16: 0 | K16: =Ownership!E305/Ownership!E311 -> 0.0745742 | L16: 0 | M16: =Ownership!E306/Ownership!E311 -> 0 | N16: 0 | O16: =Ownership!E307/Ownership!E311 -> 0.019126332 | P16: 0 | Q16: =Ownership!E308/Ownership!E311 -> 0 | R16: 0 | S16: =Ownership!E309/Ownership!E311 -> 0.0087303377 | T16: =J16*$D16 -> 0 | U16: =K16*$D16 -> 32.484521 | V16: =L16*$D16 -> 0 | W16: =M16*$D16 -> 0 | X16: =N16*$D16 -> 0 | Y16: =O16*$D16 -> 8.3314302 | Z16: =P16*$D16 -> 0 | AA16: =Q16*$D16 -> 0 | ... AC16: =S16*$D16 -> 3.8029351
A17: Azur Space Solar Power GMBH | B17: DE | C17: 70.4 | E17: 1 | F17: =Ownership!D320/Ownership!D321 -> 1 | G17: =Ownership!E320/Ownership!E321 -> 1 | H17: =F17*C17 -> 70.4 | I17: =G17*C17 -> 70.4 | J17: 0 | K17: 0 | L17: =Ownership!D316/Ownership!D321 -> 1 | M17: =Ownership!E316/Ownership!E321 -> 1 | N17: 0 | O17: 0 | P17: 0 | Q17: 0 | R17: 0 | S17: 0 | T17: =J17*$C17 -> 0 | U17: =K17*$C17 -> 0 | V17: =L17*$C17 -> 70.4 | W17: =M17*$C17 -> 70.4 | X17: =N17*$C17 -> 0 | Y17: =O17*$C17 -> 0 | Z17: =P17*$C17 -> 0 | AA17: =Q17*$C17 -> 0 | ... AC17: =S17*$C17 -> 0 | AD17: 5N Plus INC | AE17: CA | AF17: - | AG17: n.a.
A18: Beyond Gravity Austria GMBH (RUAG Space GMBH) | B18: AT | C18: 56.2 | E18: 2 | F18: =Ownership!D660/Ownership!D661 -> 0 | G18: =Ownership!E660/Ownership!E661 -> 0 | H18: =F18*C18 -> 0 | I18: =G18*C18 -> 0 | J18: 0 | K18: 0 | L18: 0 | M18: 0 | N18: 0 | O18: 0 | P18: 0 | Q18: 0 | R18: 0 | S18: 0 | T18: =J18*$C18 -> 0 | U18: =K18*$C18 -> 0 | V18: =L18*$C18 -> 0 | W18: =M18*$C18 -> 0 | X18: =N18*$C18 -> 0 | Y18: =O18*$C18 -> 0 | Z18: =P18*$C18 -> 0 | AA18: =Q18*$C18 -> 0 | ... AC18: =S18*$C18 -> 0 | AD18: Schweizerische Eidgenossenschaft | AE18: CH | AF18: - | AG18: -
A19: Beyond Gravity Sweden AB (RUAG Space AB) | B19: SE | C19: 88.4 | E19: 1 | F19: =Ownership!D671/Ownership!D672 -> 0 | G19: =Ownership!E671/Ownership!E672 -> 1 | H19: =F19*C19 -> 0 | I19: =G19*C19 -> 88.4 | J19: 0 | K19: 0 | L19: 0 | M19: 0 | N19: 0 | O19: 0 | P19: 0 | Q19: =Ownership!E669/Ownership!E672 -> 1 | R19: 0 | S19: 0 | T19: =J19*$C19 -> 0 | U19: =K19*$C19 -> 0 | V19: =L19*$C19 -> 0 | W19: =M19*$C19 -> 0 | X19: =N19*$C19 -> 0 | Y19: =O19*$C19 -> 0 | Z19: =P19*$C19 -> 0 | AA19: =Q19*$C19 -> 88.4 | ... AC19: =S19*$C19 -> 0 | AD19: Schweizerische Eidgenossenschaft | AE19: CH | AF19: - | AG19: -
A20: CGI Deutschland BV & CO.KG | B20: DE | C20: 634.4 | E20: 2 | F20: =Ownership!D895/Ownership!D896 -> 1 | G20: =Ownership!E895/Ownership!E896 -> 0.98251963 | H20: =F20*C20 -> 634.4 | I20: =G20*C20 -> 623.31045 | J20: =Ownership!D890/Ownership!D896 -> 0.088998764 | K20: =Ownership!E890/Ownership!E896 -> 0.12854882 | L20: =Ownership!D891/Ownership!D896 -> 0.81307513 | M20: =Ownership!E891/Ownership!E896 -> 0.68210558 | N20: =Ownership!D892/Ownership!D896 -> 0 | O20: =Ownership!E892/Ownership!E896 -> 0.017480374 | P20: =Ownership!D893/Ownership!D896 -> 0 | Q20: =Ownership!E893/Ownership!E896 -> 0.01311028 | R20: =Ownership!D894/Ownership!D896 -> 0 | S20: =Ownership!E894/Ownership!E896 -> 0.015521366 | T20: =J20*$C20 -> 56.460816 | U20: =K20*$C20 -> 81.551368 | V20: =L20*$C20 -> 515.81486 | W20: =M20*$C20 -> 432.72778 | X20: =N20*$C20 -> 0 | Y20: =O20*$C20 -> 11.089549 | Z20: =P20*$C20 -> 0 | AA20: =Q20*$C20 -> 8.3171619 | ... AC20: =S20*$C20 -> 9.8467548 | AD20: CGI INC | AE20: CA | AF20: 9387.3 | AG20: 89
A21: CS Group - Germany GMBH | B21: DE | E21: 1 | F21: =Ownership!D972/Ownership!D973 -> 0.012942282 | G21: =Ownership!E972/Ownership!E973 -> 0.30248307 | H21: =F21*C21 -> 0 | I21: =G21*C21 -> 0 | J21: =Ownership!D967/Ownership!D973 -> 0 | K21: =Ownership!E967/Ownership!E973 -> 0.16301193 | L21: =Ownership!D968/Ownership!D973 -> 0.012942282 | M21: =Ownership!E968/Ownership!E973 -> 0.0058045792 | N21: =Ownership!D969/Ownership!D973 -> 0 | O21: =Ownership!E969/Ownership!E973 -> 0.0090293454 | P21: =Ownership!D970/Ownership!D973 -> 0 | Q21: =Ownership!E970/Ownership!E973 -> 0.0041921961 | R21: =Ownership!D971/Ownership!D973 -> 0 | S21: =Ownership!E971/Ownership!E973 -> 0.032570139 | T21: =J21*$C21 -> 0 | U21: =K21*$C21 -> 0 | V21: =L21*$C21 -> 0 | W21: =M21*$C21 -> 0 | X21: =N21*$C21 -> 0 | Y21: =O21*$C21 -> 0 | Z21: =P21*$C21 -> 0 | AA21: =Q21*$C21 -> 0 | ... AC21: =S21*$C21 -> 0 | AD21: Sopra Steria Group SA | AE21: FR | AF21: 5460.6 | AG21: 66
A22: CS Group - Romania SA | B22: RO | D22: 4.4 | E22: 4 | F22: =Ownership!D972/Ownership!D973 -> 0.012942282 | G22: =Ownership!E972/Ownership!E973 -> 0.30248307 | H22: =F22*D22 -> 0.056946039 | I22: =G22*D22 -> 1.3309255 | J22: =J21 -> 0 | K22: =K21 -> 0.16301193 | L22: =L21 -> 0.012942282 | M22: =M21 -> 0.0058045792 | N22: =N21 -> 0 | O22: =O21 -> 0.0090293454 | P22: =P21 -> 0 | Q22: =Q21 -> 0.0041921961 | ... S22: =S21 -> 0.032570139 | T22: =J22*$D22 -> 0 | U22: =K22*$D22 -> 0.7172525 | V22: =L22*$D22 -> 0.056946039 | W22: =M22*$D22 -> 0.025540148 | X22: =N22*$D22 -> 0 | Y22: =O22*$D22 -> 0.03972912 | Z22: =P22*$D22 -> 0 | AA22: =Q22*$D22 -> 0.018445663 | ... AC22: =S22*$D22 -> 0.14330861 | AD22: Sopra Steria Group SA | AE22: FR | AF22: 5460.6 | AG22: 66
A23: CS Group France | B23: FR | D23: 221.6 | E23: 3 | F23: =Ownership!D972/Ownership!D973 -> 0.012942282 | G23: =Ownership!E972/Ownership!E973 -> 0.30248307 | H23: =F23*D23 -> 2.8680096 | I23: =G23*D23 -> 67.030248 | J23: =J22 -> 0 | K23: =K22 -> 0.16301193 | L23: =L22 -> 0.012942282 | M23: =M22 -> 0.0058045792 | N23: =N22 -> 0 | O23: =O22 -> 0.0090293454 | P23: =P22 -> 0 | Q23: =Q22 -> 0.0041921961 | ... S23: =S22 -> 0.032570139 | T23: =J23*$D23 -> 0 | U23: =K23*$D23 -> 36.123444 | V23: =L23*$D23 -> 2.8680096 | W23: =M23*$D23 -> 1.2862947 | X23: =N23*$D23 -> 0 | Y23: =O23*$D23 -> 2.0009029 | Z23: =P23*$D23 -> 0 | AA23: =Q23*$D23 -> 0.92899065 | ... AC23: =S23*$D23 -> 7.2175427 | AD23: Sopra Steria Group SA | AE23: FR | AF23: 5460.6 | AG23: 66
A24: Dassault Aviation | B24: FR | D24: 7569.4 | E24: 29 | F24: =Ownership!D365/Ownership!D366 -> 0 | G24: =Ownership!E365/Ownership!E366 -> 0.1145923 | H24: =F24*D24 -> 0 | I24: =G24*D24 -> 867.39494 | J24: 0 | K24: =Ownership!E360/Ownership!E366 -> 0.087344529 | L24: 0 | M24: =Ownership!E361/Ownership!E366 -> 0.0040287881 | N24: 0 | O24: =Ownership!E362/Ownership!E366 -> 0.010058272 | P24: 0 | Q24: 0 | R24: 0 | S24: =Ownership!E364/Ownership!E366 -> 0.0095347985 | T24: =J24*$D24 -> 0 | U24: =K24*$D24 -> 661.14568 | V24: =L24*$D24 -> 0 | W24: =M24*$D24 -> 30.495509 | X24: =N24*$D24 -> 0 | Y24: =O24*$D24 -> 76.135087 | Z24: =P24*$D24 -> 0 | AA24: =Q24*$D24 -> 0 | ... AC24: =S24*$D24 -> 72.172704 | AD24: Rond Point Immobilier | AE24: FR | AF24: 1132.6 | AG24: 16
A25: Deimos Engenharia | B25: PT | D25: 7.8 | E25: 2 | F25: =Ownership!D381/Ownership!D382 -> 0 | G25: =Ownership!E381/Ownership!E382 -> 0 | H25: =F25*D25 -> 0 | I25: =G25*D25 -> 0 | J25: 0 | K25: 0 | L25: 0 | M25: 0 | N25: 0 | O25: 0 | P25: 0 | Q25: 0 | R25: 0 | S25: 0 | T25: =J25*$D25 -> 0 | U25: =K25*$D25 -> 0 | V25: =L25*$D25 -> 0 | W25: =M25*$D25 -> 0 | X25: =N25*$D25 -> 0 | Y25: =O25*$D25 -> 0 | Z25: =P25*$D25 -> 0 | AA25: =Q25*$D25 -> 0 | ... AC25: =S25*$D25 -> 0 | AD25: Cantiles XXI SL | AE25: FR | AF25: 3563.5 | AG25: 3
A26: Deimos Space Romania | B26: RO | D26: 1.5 | E26: 1 | F26: =Ownership!D381/Ownership!D382 -> 0 | G26: =Ownership!E381/Ownership!E382 -> 0 | H26: =F26*D26 -> 0 | I26: =G26*D26 -> 0 | J26: 0 | K26: 0 | L26: 0 | M26: 0 | N26: 0 | O26: 0 | P26: 0 | Q26: 0 | R26: 0 | S26: 0 | T26: =J26*$D26 -> 0 | U26: =K26*$D26 -> 0 | V26: =L26*$D26 -> 0 | W26: =M26*$D26 -> 0 | X26: =N26*$D26 -> 0 | Y26: =O26*$D26 -> 0 | Z26: =P26*$D26 -> 0 | AA26: =Q26*$D26 -> 0 | ... AC26: =S26*$D26 -> 0 | AD26: Cantiles XXI SL | AE26: ES | AF26: 3563.5 | AG26: 3
A27: Deimos Space, Sociedad Limitada Unipersonal | B27: ES | C27: 30.2 | E27: 1 | F27: =Ownership!D381/Ownership!D382 -> 0 | G27: =Ownership!E381/Ownership!E382 -> 0 | H27: =F27*C27 -> 0 | I27: =G27*C27 -> 0 | J27: 0 | K27: 0 | L27: 0 | M27: 0 | N27: 0 | O27: 0 | P27: 0 | Q27: 0 | R27: 0 | S27: 0 | T27: =J27*$C27 -> 0 | U27: =K27*$C27 -> 0 | V27: =L27*$C27 -> 0 | W27: =M27*$C27 -> 0 | X27: =N27*$C27 -> 0 | Y27: =O27*$C27 -> 0 | Z27: =P27*$C27 -> 0 | AA27: =Q27*$C27 -> 0 | ... AC27: =S27*$C27 -> 0 | AD27: Cantiles XXI SL | AE27: ES | AF27: 3563.5 | AG27: 3
A28: e-GEOS SPA | B28: IT | C28: 89.7 | E28: 2 | F28: =Ownership!D594/Ownership!D595 -> 0.2596837 | G28: =Ownership!E594/Ownership!E595 -> 0.4490146 | H28: =F28*C28 -> 23.293628 | I28: =G28*C28 -> 40.27661 | J28: =Ownership!D589/Ownership!D595 -> 0.14852166 | K28: =Ownership!E589/Ownership!E595 -> 0.35688152 | L28: =Ownership!D590/Ownership!D595 -> 0 | M28: =Ownership!E590/Ownership!E595 -> 0 | N28: =Ownership!D591/Ownership!D595 -> 0.076323631 | O28: =Ownership!E591/Ownership!E595 -> 0.02564311 | P28: =Ownership!D592/Ownership!D595 -> 0 | Q28: =Ownership!E592/Ownership!E595 -> 0.0032521383 | R28: =Ownership!D593/Ownership!D595 -> 0.034838414 | S28: =Ownership!E593/Ownership!E595 -> 0.052196819 | T28: =J28*$C28 -> 13.322393 | U28: =K28*$C28 -> 32.012273 | V28: =L28*$C28 -> 0 | W28: =M28*$C28 -> 0 | X28: =N28*$C28 -> 6.8462297 | Y28: =O28*$C28 -> 2.300187 | Z28: =P28*$C28 -> 0 | AA28: =Q28*$C28 -> 0.2917168 | ... AC28: =S28*$C28 -> 4.6820547 | AD28: Leonardo SPA | AE28: IT | AF28: 16515.2 | AG28: 47
A29: Elecnor Infrastrutture e Aerospaziale | B29: IT | C29: 1.6 | E29: 2 | F29: =Ownership!D381/Ownership!D382 -> 0 | G29: =Ownership!E381/Ownership!E382 -> 0 | H29: =F29*C29 -> 0 | I29: =G29*C29 -> 0 | J29: 0 | K29: 0 | L29: 0 | M29: 0 | N29: 0 | O29: 0 | P29: 0 | Q29: 0 | R29: 0 | S29: 0 | T29: =J29*$C29 -> 0 | U29: =K29*$C29 -> 0 | V29: =L29*$C29 -> 0 | W29: =M29*$C29 -> 0 | X29: =N29*$C29 -> 0 | Y29: =O29*$C29 -> 0 | Z29: =P29*$C29 -> 0 | AA29: =Q29*$C29 -> 0 | ... AC29: =S29*$C29 -> 0 | AD29: Cantiles XXI SL | AE29: ES | AF29: 3563.5 | AG29: 3
A30: Enpulsion GMBH | B30: AT | E30: 8 | F30: =Ownership!D59/Ownership!D60 -> 0 | G30: =Ownership!E59/Ownership!E60 -> 0 | H30: =F30*C30 -> 0 | I30: =G30*C30 -> 0 | J30: 0 | K30: 0 | L30: 0 | M30: 0 | N30: 0 | O30: 0 | P30: 0 | Q30: 0 | R30: 0 | S30: 0 | T30: =J30*$C30 -> 0 | U30: =K30*$C30 -> 0 | V30: =L30*$C30 -> 0 | W30: =M30*$C30 -> 0 | X30: =N30*$C30 -> 0 | Y30: =O30*$C30 -> 0 | Z30: =P30*$C30 -> 0 | AA30: =Q30*$C30 -> 0 | ... AC30: =S30*$C30 -> 0 | AD30: mr Alexander Reissner
A31: GMV Aerospace & Defence SA | B31: ES | C31: 186.5 | E31: 1 | F31: =Ownership!D394/Ownership!D395 -> 0 | G31: =Ownership!E394/Ownership!E395 -> 0 | H31: =F31*C31 -> 0 | I31: =G31*C31 -> 0 | J31: 0 | K31: 0 | L31: 0 | M31: 0 | N31: 0 | O31: 0 | P31: 0 | Q31: 0 | R31: 0 | S31: 0 | T31: =J31*$C31 -> 0 | U31: =K31*$C31 -> 0 | V31: =L31*$C31 -> 0 | W31: =M31*$C31 -> 0 | X31: =N31*$C31 -> 0 | Y31: =O31*$C31 -> 0 | Z31: =P31*$C31 -> 0 | AA31: =Q31*$C31 -> 0 | ... AC31: =S31*$C31 -> 0 | AD31: GMV Innovating Solutions SL | AE31: ES | AF31: 288.2 | AG31: 2
A32: GMV GMBH | B32: DE | C32: 24.9 | E32: 1 | F32: =Ownership!D394/Ownership!D395 -> 0 | G32: =Ownership!E394/Ownership!E395 -> 0 | H32: =F32*C32 -> 0 | I32: =G32*C32 -> 0 | J32: 0 | K32: 0 | L32: 0 | M32: 0 | N32: 0 | O32: 0 | P32: 0 | Q32: 0 | R32: 0 | S32: 0 | T32: =J32*$C32 -> 0 | U32: =K32*$C32 -> 0 | V32: =L32*$C32 -> 0 | W32: =M32*$C32 -> 0 | X32: =N32*$C32 -> 0 | Y32: =O32*$C32 -> 0 | Z32: =P32*$C32 -> 0 | AA32: =Q32*$C32 -> 0 | ... AC32: =S32*$C32 -> 0 | AD32: GMV Innovating Solutions SL | AE32: ES | AF32: 288.2 | AG32: 2
A33: GMV Innovating Solutions BV | B33: NL | E33: 1 | F33: =Ownership!D394/Ownership!D395 -> 0 | G33: =Ownership!E394/Ownership!E395 -> 0 | H33: =F33*C33 -> 0 | I33: =G33*C33 -> 0 | J33: 0 | K33: 0 | L33: 0 | M33: 0 | N33: 0 | O33: 0 | P33: 0 | Q33: 0 | R33: 0 | S33: 0 | T33: =J33*$C33 -> 0 | U33: =K33*$C33 -> 0 | V33: =L33*$C33 -> 0 | W33: =M33*$C33 -> 0 | X33: =N33*$C33 -> 0 | Y33: =O33*$C33 -> 0 | Z33: =P33*$C33 -> 0 | AA33: =Q33*$C33 -> 0 | ... AC33: =S33*$C33 -> 0 | AD33: GMV Innovating Solutions SL | AE33: ES | AF33: 288.2 | AG33: 2
A34: GMV Innovating Solutions SARL | B34: FR | D34: 8.6 | E34: 3 | F34: =Ownership!D394/Ownership!D395 -> 0 | G34: =Ownership!E394/Ownership!E395 -> 0 | H34: =F34*D34 -> 0 | I34: =G34*D34 -> 0 | J34: 0 | K34: 0 | L34: 0 | M34: 0 | N34: 0 | O34: 0 | P34: 0 | Q34: 0 | R34: 0 | S34: 0 | T34: =J34*$D34 -> 0 | U34: =K34*$D34 -> 0 | V34: =L34*$D34 -> 0 | W34: =M34*$D34 -> 0 | X34: =N34*$D34 -> 0 | Y34: =O34*$D34 -> 0 | Z34: =P34*$D34 -> 0 | AA34: =Q34*$D34 -> 0 | ... AC34: =S34*$D34 -> 0 | AD34: GMV Innovating Solutions SL | AE34: ES | AF34: 288.2 | AG34: 2
A35: GMV Innovating Solutions Sp.z o.o. | B35: PL | D35: 8.7 | E35: 1 | F35: =Ownership!D394/Ownership!D395 -> 0 | G35: =Ownership!E394/Ownership!E395 -> 0 | H35: =F35*D35 -> 0 | I35: =G35*D35 -> 0 | J35: 0 | K35: 0 | L35: 0 | M35: 0 | N35: 0 | O35: 0 | P35: 0 | Q35: 0 | R35: 0 | S35: 0 | T35: =J35*$D35 -> 0 | U35: =K35*$D35 -> 0 | V35: =L35*$D35 -> 0 | W35: =M35*$D35 -> 0 | X35: =N35*$D35 -> 0 | Y35: =O35*$D35 -> 0 | Z35: =P35*$D35 -> 0 | AA35: =Q35*$D35 -> 0 | ... AC35: =S35*$D35 -> 0 | AD35: GMV Innovating Solutions SL | AE35: ES | AF35: 288.2 | AG35: 2
A36: GMV Innovating Solutions SRL | B36: RO | D36: 5.5 | E36: 1 | F36: =Ownership!D394/Ownership!D395 -> 0 | G36: =Ownership!E394/Ownership!E395 -> 0 | H36: =F36*D36 -> 0 | I36: =G36*D36 -> 0 | J36: 0 | K36: 0 | L36: 0 | M36: 0 | N36: 0 | O36: 0 | P36: 0 | Q36: 0 | R36: 0 | S36: 0 | T36: =J36*$D36 -> 0 | U36: =K36*$D36 -> 0 | V36: =L36*$D36 -> 0 | W36: =M36*$D36 -> 0 | X36: =N36*$D36 -> 0 | Y36: =O36*$D36 -> 0 | Z36: =P36*$D36 -> 0 | AA36: =Q36*$D36 -> 0 | ... AC36: =S36*$D36 -> 0 | AD36: GMV Innovating Solutions SL | AE36: ES | AF36: 288.2 | AG36: 2
A37: GMV Innovating Solutions SRL (B) | B37: BE | E37: 1 | F37: =Ownership!D394/Ownership!D395 -> 0 | G37: =Ownership!E394/Ownership!E395 -> 0 | H37: =F37*C37 -> 0 | I37: =G37*C37 -> 0 | J37: 0 | K37: 0 | L37: 0 | M37: 0 | N37: 0 | O37: 0 | P37: 0 | Q37: 0 | R37: 0 | S37: 0 | T37: =J37*$C37 -> 0 | U37: =K37*$C37 -> 0 | V37: =L37*$C37 -> 0 | W37: =M37*$C37 -> 0 | X37: =N37*$C37 -> 0 | Y37: =O37*$C37 -> 0 | Z37: =P37*$C37 -> 0 | AA37: =Q37*$C37 -> 0 | ... AC37: =S37*$C37 -> 0 | AD37: GMV Innovating Solutions SL | AE37: ES | AF37: 288.2 | AG37: 2
A38: GMV Soluciones Globales Internet SA | B38: ES | C38: 56 | E38: 1 | F38: =Ownership!D394/Ownership!D395 -> 0 | G38: =Ownership!E394/Ownership!E395 -> 0 | H38: =F38*C38 -> 0 | I38: =G38*C38 -> 0 | J38: 0 | K38: 0 | L38: 0 | M38: 0 | N38: 0 | O38: 0 | P38: 0 | Q38: 0 | R38: 0 | S38: 0 | T38: =J38*$C38 -> 0 | U38: =K38*$C38 -> 0 | V38: =L38*$C38 -> 0 | W38: =M38*$C38 -> 0 | X38: =N38*$C38 -> 0 | Y38: =O38*$C38 -> 0 | Z38: =P38*$C38 -> 0 | AA38: =Q38*$C38 -> 0 | ... AC38: =S38*$C38 -> 0 | AD38: GMV Innovating Solutions SL | AE38: ES | AF38: 288 | AG38: 2
A39: GMVIS Skysoft SA | B39: PT | D39: 9.5 | E39: 1 | F39: =Ownership!D394/Ownership!D395 -> 0 | G39: =Ownership!E394/Ownership!E395 -> 0 | H39: =F39*D39 -> 0 | I39: =G39*D39 -> 0 | J39: 0 | K39: 0 | L39: 0 | M39: 0 | N39: 0 | O39: 0 | P39: 0 | Q39: 0 | R39: 0 | S39: 0 | T39: =J39*$D39 -> 0 | U39: =K39*$D39 -> 0 | V39: =L39*$D39 -> 0 | W39: =M39*$D39 -> 0 | X39: =N39*$D39 -> 0 | Y39: =O39*$D39 -> 0 | Z39: =P39*$D39 -> 0 | AA39: =Q39*$D39 -> 0 | ... AC39: =S39*$D39 -> 0 | AD39: GMV Innovating Solutions SL | AE39: ES | AF39: 288.2 | AG39: 2
A40: Indra Sistemas SA | B40: ES | C40: 3864.2 | E40: 148 | F40: =Ownership!D501/Ownership!D502 -> 0.36546339 | G40: =Ownership!E501/Ownership!E502 -> 0.57145585 | H40: =F40*C40 -> 1412.2236 | I40: =G40*C40 -> 2208.2197 | J40: =Ownership!D496/Ownership!D502 -> 0.18010753 | K40: =Ownership!E496/Ownership!E502 -> 0.34830855 | L40: =Ownership!D497/Ownership!D502 -> 0.00025601639 | M40: =Ownership!E497/Ownership!E502 -> 0.0054638327 | N40: =Ownership!D498/Ownership!D502 -> 0.10023041 | O40: =Ownership!E498/Ownership!E502 -> 0.006010216 | P40: =Ownership!D499/Ownership!D502 -> 0 | Q40: =Ownership!E499/Ownership!E502 -> 0.0033875763 | R40: =Ownership!D500/Ownership!D502 -> 0.034178187 | S40: =Ownership!E500/Ownership!E502 -> 0.061959863 | T40: =J40*$C40 -> 695.97151 | U40: =K40*$C40 -> 1345.9339 | V40: =L40*$C40 -> 0.98929852 | W40: =M40*$C40 -> 21.113342 | X40: =N40*$C40 -> 387.31037 | Y40: =O40*$C40 -> 23.224677 | Z40: =P40*$C40 -> 0 | AA40: =Q40*$C40 -> 13.090272 | ... AC40: =S40*$C40 -> 239.4253
...

Sheet Ownership
A1: Institution | B1: Country | C1: Type | D1: Direct ownership | E1: Indirect ownership
A2: ArianeGroup Holding (owner of Eurockot/ArianeGroup SAS/ArianeGroup GMBH/Arianespace)
A3: Airbus Defence & Space Holding France SAS | B3: FR | C3: C | E3: 0.5
A4: Safran | B4: FR | C4: C | D4: 0.5
A5: Agence des Participations de l'Etat | B5: FR | C5: S | E5: =D4*17.76% -> 0.0888
A6: Personnel de Safran | B6: - | C6: M | E6: =D4*10.29% -> 0.05145
A7: Safran Investissements | B7: FR | C7: F | E7: =D4*8.98% -> 0.0449
A8: Actionnaires Individuels | B8: - | C8: D | E8: =D4*8% -> 0.04
A9: The Children's Investment Master Fund | B9: KY | C9: E | E9: =D4*6.25% -> 0.03125
A10: FCPE Safran Investissement | B10: - | C10: E | E10: =D4*5.73% -> 0.02865
A11: TCI Fund Management UK Limited | B11: UK | C11: E | E11: =D4*4.79% -> 0.02395
A12: HSBC Holdings PLC | B12: UK | C12: B | E12: =D4*3.16% -> 0.0158
A13: CNP Assurances | B13: FR | C13: A | E13: =D4*2.75% -> 0.01375
A14: FCPE Avenir Safran | B14: - | C14: E | E14: =D4*1.99% -> 0.00995
A15: Harris Associates LP | B15: US | C15: C | E15: =D4*1.96% -> 0.0098
A16: Egerton Capital UK LLP | B16: UK | C16: F | E16: =D4*1.94% -> 0.0097
A17: Tweedy Browne Co LLC | B17: US | C17: C | E17: =D4*1.61% -> 0.00805
A18: Meritage Investment Partners LLC | B18: US | C18: F | E18: =D4*1.06% -> 0.0053
A19: Wellington Management Company LLP | B19: US | C19: C | E19: =D4*1.06% -> 0.0053
A20: Amundi Asset Management | B20: FR | C20: C | E20: =D4*0.99% -> 0.00495
A21: Lone Pine Capital LLC | B21: US | C21: Y | E21: =D4*0.97% -> 0.00485
A22: Viking Global Investors LP | B22: US | C22: P | E22: =D4*0.97% -> 0.00485
A23: Peugeot 1810 | B23: FR | C23: C | E23: =D4*0.8% -> 0.004
A24: Fonds Strategique de Participations | B24: FR | C24: E | E24: =D4*0.75% -> 0.00375
A25: PSA ID | B25: FR | C25: C | E25: =D4*0.7% -> 0.0035
A26: Self Owned | B26: - | C26: H | E26: =D4*0.63% -> 0.00315
A27: Bridgewater Associates LP | B27: US | C27: F | E27: =D4*0.46% -> 0.0023
A28: Banque Fédérative du Crédit Mutuel | B28: FR | C28: B | E28: =D4*0.3% -> 0.0015
A29: Salaries | B29: - | C29: M | E29: =D4*0.27% -> 0.00135
A30: Talos Capital Designated Activity Company | B30: IE | C30: E | E30: =D4*0.26% -> 0.0013
A31: CIFF Capital UK LP | B31: UK | C31: C | E31: =D4*0.15% -> 0.00075
A32: Peugeot Invest Assets | B32: UK | C32: F | E32: =D4*0.1% -> 0.0005
A33: US | D33: 0 | E33: =SUM(E15,E17:E19,E21:E22,E27) -> 0.04045
A34: Canada | D34: 0 | E34: 0
A35: UK | D35: 0 | E35: =SUM(E11:E12,E16,E31:E32) -> 0.0507
A36: Switzerland | D36: 0 | E36: 0
A37: Norway | D37: 0 | E37: 0
A38: Non-EU ownership | D38: 0 | E38: =SUM(E9,E11:E12,E15:E19,E21:E22,E27,E31:E32) -> 0.1224
A39: Total | D39: =SUM(D3:D32) -> 0.5 | E39: =SUM(E3:E32) -> 0.9234
A41: Enpulsion gmbh
...

Sheet M&A
A1: Case | B1: Country | C1: target company | D1: Country | E1: acquiring company | F1: Non-EU takeover of EU company
A2: M.53 | B2: US | C2: Havilland (Boeing company) | D2: FR/IT | E2: Aerospatiale/Alenia-Aeritalia e Selenia spa | F2: No
A3: M.178 | B3: SW | C3: Ericson Radar Electronics | D3: SW | E3: Saab-Scania Combitech AB | F3: No
A4: M.237 | B4: NL | C4: Fokker | D4: DE | E4: Daimler-Benz | F4: No
A5: M.877 | B5: US | C5: MDC | D5: US | E5: Boeing | F5: No
A6: M.1185
A7: M.1198 | B7: SW | C7: Saab AB | D7: UK/SW | E7: British Aerospace plc/Investor AB | F7: No
A8: M.1309 | B8: FR | C8: Matra Hautes Technologies/Aérospatiale SNI | D8: FR | E8: Etat Francais/Lagardère SCA | F8: No
A9: M.1438 | B9: US | C9: MES (part of GEC) | D9: UK | E9: British Aerospace plc | F9: No
A10: M.1601 | B10: US | C10: Honeywell | D10: US | E10: AlliedSignal | F10: No
A11: M.1786 | B11: FR | C11: Thomson-CSF (Thales) | D11: US | E11: General Electric company | F11: Yes (jv)
A12: M.1636 | B12: FR | C12: Astrium | D12: FR/DE | E12: Matra Marconi Space/DaimlerChrysler Aerospace AG | F12: No
A13: M.1745 | B13: NL | C13: EADS NV (Airbus) | D13: DE/FR/ES | E13: DaimlerChrysler AG/Lagardère SCA/French State/ Sociedad Estatal de Participaciones Industriales | F13: No
A14: M.1879 | B14: US | C14: Hughes Electronics Corporation | D14: US | E14: Boeing | F14: No
A15: M.2061 | B15: NL | C15: Airbus | D15: NL | E15: EADS NV | F15: No
A16: M.2168 | B16: FR | C16: Hurel-Dubois | D16: FR | E16: e SociÈtÈ Nationale díEtude et de Construction de Moteurs díAviation | F16: No
A17: M.2183 | B17: UK | C17: TI Group plc | D17: UK | E17: Smiths Industries plc | F17: No
A18: M.2437 | B18: JPN | C18: Toshiba | D18: JPN | E18: NEC | F18: No
... A33: M.5151 | B33: US | C33: Global Aeronautica LLC | D33: US/IT | E33: Boeing/Finmeccanica Group | F33: No
A34: M.5276 | B34: NL | C34: Airbus (Laupheim manufacturing site) | E34: Diehl Stiftung & Co.KG/Thales SA | F34: No
A35: M.5357 | B35: NL | C35: Airbus SAS | D35: UK | E35: GKN plc | F35: No
A36: M.5168 | B36: UK | C36: Surrey Satellite Technology Limited | D36: NL | E36: EADS | F36: No
A37: M.5426 | B37: FR | C37: Thales | D37: FR | E37: Dassault Aviation | F37: No
A38: M.5667 | B38: CA | C38: Mecachrome International Inc. | D38: FR/CA | E38: ACE Management/Fonds de solidarité des travailleurs du Québec/ la Caisse des Dépôts et Consignations
A39: M.5668 | B39: FR | C39: Safran | D39: Singapore | E39: Singapore Airlines Limited | F39: Yes
A40: M.6581 | B40: SW | C40: Volvo Aero | D40: UK | E40: GKN plc | F40: No
A41: M.6844 | B41: IT | C41: Avio spa | D41: US | E41: General Electric company | F41: Yes
A42: M.7144 | B42: ES | C42: Synergy Industry and Technology, S.A. | D42: US | E42: Apollo Group
A43: M.7353 | B43: NL | C43: Airbus | D43: FR | E43: Safran | F43: No (JV)
A44: M.7676 | B44: NL | C44: Fokker Technologies Group BV | D44: UK | E44: GKN plc | F44: No
A45: M.7724 | B45: FR | C45: Arianespace SA | D45: FR | E45: Airbus Safran Launchers/Safran | F45: No
A46: M.8425 | B46: FR | C46: Zodiac Aerospace | D46: FR | E46: Safran | F46: No
A47: M.8688 | B47: US | C47: Orbital ATK | D47: US | E47: Northrop Grumman | F47: No
A48: M.8814 | B48: UK | C48: GKN plc | D48: UK | E48: Molrose Industries plc | F48: No
A49: M.8858 | B49: FR | C49: Safran | D49: US | E49: Boeing | F49: Yes (jv)
A50: M.8658 | B50: US | C50: Rockwell Collins | D50: US | E50: United Technologies Corporation | F50: No
A51: M.10506 | B51: UK | C51: Meggitt | D51: US | E51: Parker-Hannifin Corporation | F51: No

Sheet Tenders
A1: tender_id | B1: tender_publications_firstdContractAwardDate | C1: tender_publications_lastContractAwardDate | D1: lot_status | E1: lot_contractSignatureDate | F1: lot_cancellationDate | G1: tender_year | H1: tender_title | I1: tender_country | J1: bidder_country | K1: price | L1: bidder_name | M1: buyer_name | N1: buyer_buyerType | O1: bid_price_EUR | P1: tender_finalPrice_EUR | Q1: tender_estimatedPrice_EUR
A2: 89f99677-96a9-4021-a712-b4f58762b84f | B2: 42345 | C2: 42345 | D2: AWARDED | E2: 42346 | G2: 2015 | H2: Inel etansare 5125A-287-2 | I2: RO | J2: RO | K2: 194.48 | L2: AEROSTAR S.A. | M2: Unitatea Militara nr. 01969 -Campia Turzii | N2: NATIONAL_AGENCY | O2: 194.48
A3: ce946a21-3a23-4bb8-9392-87387eab2568 | B3: 43447 | C3: 43447 | D3: AWARDED | E3: 43447 | G3: 2018 | H3: Distantier CTP-placa flexibila | I3: RO | J3: RO | K3: 199.67 | L3: AEROTEH S.A. | M3: Unitatea Militara nr. 01969 -Campia Turzii | N3: NATIONAL_AGENCY | O3: 199.67
A4: 6fec0eb8-6f48-4340-bea2-227227dd71d3 | B4: 41586 | C4: 41586 | D4: AWARDED | E4: 41589 | G4: 2013 | H4: Elementi de filtrare filtru ulei CTP | I4: RO | J4: RO | K4: 800 | L4: AEROTEH S.A. | M4: Unitatea Militara nr. 01969 -Campia Turzii | N4: NATIONAL_AGENCY | O4: 800
A5: 9e085539-41dd-406d-ad3e-d89d4251da7a | B5: 42549 | C5: 42549 | D5: AWARDED | E5: 42550 | G5: 2016 | H5: Inel etansare 0257725 | I5: RO | J5: RO | L5: AEROSTAR S.A. | M5: Unitatea Militara nr. 01969 -Campia Turzii | N5: NATIONAL_AGENCY
A6: c8001d91-d725-4a02-928a-374f5f2d5ff0 | B6: 41787 | C6: 41787 | D6: AWARDED | E6: 41788 | G6: 2014 | H6: INEL DE ETANSARE EXTERIOR CAPAC FILTRU HIDRAULIC REPER FG11SN-1 - 212010 | I6: RO | J6: RO | L6: AEROSTAR S.A. | M6: Unitatea Militara nr. 01969 -Campia Turzii | N6: NATIONAL_AGENCY
A7: 40a6f028-c7bd-487b-be59-d443dc4f7811 | B7: 42549 | C7: 42549 | D7: AWARDED | E7: 42550 | G7: 2016 | H7: Conducta 76-5513-10-28 | I7: RO | J7: RO | K7: 497.97 | L7: AEROSTAR S.A. | M7: Unitatea Militara nr. 01969 -Campia Turzii | N7: NATIONAL_AGENCY | O7: 497.97
A8: 285151ec-71c5-4036-ae66-4377926f5196 | B8: 42639 | C8: 42639 | D8: AWARDED | E8: 42639 | G8: 2016 | H8: Masca de oxigen pilot MBU 12/P | I8: RO | J8: RO | K8: 343665 | L8: AEROFINA S.A. | M8: Ministerul Apararii U.M. 02512Z | N8: NATIONAL_AUTHORITY | O8: 343665
A9: 089604f0-00e9-4d0a-88b2-0d9b248294b6 | B9: 43746 | C9: 43746 | D9: AWARDED | E9: 43747 | G9: 2019 | H9: GARNITURA ASL 94-6402-161 GARNITURA ASL 74-0200-1005 | I9: RO | J9: RO | K9: 1024.66 | L9: AEROSTAR | M9: Ministerul Apararii Nationale - U.M.01912 BORCEA | O9: 1024.66
A10: 76735d79-2043-4585-8abf-08cb6bf73bda | B10: 41787 | C10: 41787 | D10: AWARDED | E10: 41788 | G10: 2014 | H10: INEL DE ETANSARE CORP-PAHAR FILTRU HIDRAULIC REPER 11GF4SN-1 - 212003 | I10: RO | J10: RO | K10: 179.38 | L10: AEROSTAR S.A. | M10: Unitatea Militara nr. 01969 -Campia Turzii | N10: NATIONAL_AGENCY | O10: 179.38
A11: bf85813a-49ec-4a21-a9d7-0b98b15c8024 | B11: 42345 | C11: 42345 | D11: AWARDED | E11: 42346 | G11: 2015 | H11: Inel etansare 74-0200-1008 | I11: RO | J11: RO | K11: 234.52 | L11: AEROSTAR S.A. | M11: Unitatea Militara nr. 01969 -Campia Turzii | N11: NATIONAL_AGENCY | O11: 234.52
A12: bbcae0aa-d56e-4709-b7df-c7631783356d | B12: 42550 | C12: 42550 | D12: AWARDED | E12: 42550 | G12: 2016 | H12: Punte de metalizare cu 3 papuci 200N1-1/12/12-90/180 | I12: RO | J12: RO | L12: AEROSTAR S.A. | M12: Unitatea Militara nr. 01969 -Campia Turzii | N12: NATIONAL_AGENCY
A13: 07918b92-1e4c-42eb-8c97-8a520449417e | B13: 41586 | C13: 41586 | D13: AWARDED | E13: 41586 | G13: 2013 | H13: Piulite cu autosigurantare | I13: RO | J13: RO | K13: 300.06 | L13: AEROTEH S.A. | M13: Unitatea Militara nr. 01969 -Campia Turzii | N13: NATIONAL_AGENCY | O13: 300.06
A14: c2546e65-3177-4278-a4b8-99eb021b719f | B14: 44118 | C14: 44118 | D14: AWARDED | E14: 44118 | G14: 2020 | H14: Racord gofrat 1655001 si Furtun IU27-15K | I14: RO | J14: RO | K14: 839.07 | L14: AEROSTAR | M14: Ministerul Apararii Nationale - U.M.01912 BORCEA | O14: 839.07
A15: 375d3e0d-91ce-4332-bf47-41a9063452d2 | B15: 42453 | C15: 42453 | D15: AWARDED | E15: 42453 | G15: 2016 | H15: Inel etansare OD87-30-4S | I15: RO | J15: RO | K15: 404.56 | L15: AEROSTAR S.A. | M15: Ministerul Apararii Nationale - U.M.01912 BORCEA | O15: 404.56
A16: 10fb0c4f-f83f-4242-92f5-fbba43efbce9 | B16: 42549 | C16: 42549 | D16: AWARDED | E16: 42550 | G16: 2016 | H16: Conducta E6U-5511-6030-654 | I16: RO | J16: RO | K16: 444.14 | L16: AEROSTAR S.A. | M16: Unitatea Militara nr. 01969 -Campia Turzii | N16: NATIONAL_AGENCY | O16: 444.14
A17: 2a3f935c-caea-4bc7-a26c-5989cbd7f28a | B17: 42345 | C17: 42345 | D17: AWARDED | E17: 42346 | G17: 2015 | H17: Conducta flexibila 76-5511-10-730 | I17: RO | J17: RO | K17: 1129.27 | L17: AEROSTAR S.A. | M17: Unitatea Militara nr. 01969 -Campia Turzii | N17: NATIONAL_AGENCY | O17: 1129.27
A18: e1276443-2058-4985-a8b8-c0490ade4e14 | B18: 42345 | C18: 42345 | D18: AWARDED | E18: 42346 | G18: 2015 | H18: Garnitura 2263A-10-1 | I18: RO | J18: RO | K18: 233.44 | L18: AEROSTAR S.A. | M18: Unitatea Militara nr. 01969 -Campia Turzii | N18: NATIONAL_AGENCY | O18: 233.44
A19: 9ca24181-ab80-4b1d-8a08-d370978851f9 | B19: 43026 | C19: 43026 | D19: AWARDED | E19: 43026 | G19: 2017 | H19: Sarma de sigurantat rezistenta la temperaturi inalte Ø0.5 mm | I19: RO | J19: RO | K19: 503.57 | L19: AEROSTAR S.A. | M19: Ministerul Apararii Nationale - U.M.01912 BORCEA | O19: 503.57
A20: 273dddb5-d310-4c0c-b6e5-4aa7cb0c1f35 | B20: 43447 | C20: 43447 | D20: AWARDED | E20: 43447 | G20: 2018 | H20: Burduf platou PRP reper 330A31-3243-00 | I20: RO | J20: RO | K20: 826.63 | L20: AEROTEH S.A. | M20: Unitatea Militara nr. 01969 -Campia Turzii | N20: NATIONAL_AGENCY | O20: 826.63
A21: bdde1e97-685e-4eeb-8506-4354b363eda6 | B21: 42143 | C21: 42143 | D21: AWARDED | E21: 42143 | G21: 2015 | H21: SPLINT INOX 2 X 40 | I21: RO | J21: RO | L21: AEROSTAR S.A. | M21: Ministerul Apararii Nationale - U.M.01912 BORCEA
A22: d4086308-29ed-44a0-8a99-aeec49bfab9a | B22: 43852 | C22: 43852 | D22: AWARDED | E22: 43857 | G22: 2020 | H22: Reparatie Modul Sursa de Alimentare, Model SPXL-750Q-P | I22: RO | J22: RO | K22: 9376 | L22: AEROSTAR | M22: Unitatea Militara 01812 | N22: NATIONAL_AUTHORITY | O22: 9376
A23: 912386ba-d0d7-46b0-b3b7-40e5a9cd8802 | B23: 42549 | C23: 42549 | D23: AWARDED | E23: 42550 | G23: 2016 | H23: Supapa 695020 | I23: RO | J23: RO | K23: 524.36 | L23: AEROSTAR S.A. | M23: Unitatea Militara nr. 01969 -Campia Turzii | N23: NATIONAL_AGENCY | O23: 524.36
A24: 0b32dd0d-ec76-4eb9-910d-972d9738a744 | B24: 42345 | C24: 42345 | D24: AWARDED | E24: 42346 | G24: 2015 | H24: Inel etansare 74-0200-1005 | I24: RO | J24: RO | K24: 333.19 | L24: AEROSTAR S.A. | M24: Unitatea Militara nr. 01969 -Campia Turzii | N24: NATIONAL_AGENCY | O24: 333.19
A25: 7b6b563a-5cfc-4e6b-b8a8-5fa6ebce7e10 | B25: 42549 | C25: 42549 | D25: AWARDED | E25: 42550 | G25: 2016 | H25: Saiba opritoare KT-102-18 | I25: RO | J25: RO | K25: 581.8 | L25: AEROSTAR S.A. | M25: Unitatea Militara nr. 01969 -Campia Turzii | N25: NATIONAL_AGENCY | O25: 581.8
A26: b30836a7-2236-4c3c-b3a0-83781c02f53d | B26: 41787 | C26: 41787 | D26: AWARDED | E26: 41788 | G26: 2014 | H26: INEL DE ETANSARE CAPAC FILTRU HIDRAULIC REPER 11GF4SN-1 - 212002 | I26: RO | J26: RO | L26: AEROSTAR S.A. | M26: Unitatea Militara nr. 01969 -Campia Turzii | N26: NATIONAL_AGENCY
A27: 6990823f-063b-46f9-a376-54c8357ec92b | B27: 42550 | C27: 42550 | D27: AWARDED | E27: 42550 | G27: 2016 | H27: Punte de metalizare cu 2 papuci 200N2-12/14-120 | I27: RO | J27: RO | L27: AEROSTAR S.A. | M27: Unitatea Militara nr. 01969 -Campia Turzii | N27: NATIONAL_AGENCY
A28: 5fba905f-0ad2-40af-b044-3b6122da4782 | B28: 42550 | C28: 42550 | D28: AWARDED | E28: 42550 | G28: 2016 | H28: Punte de metalizare cu 3 papuci 200N1-1-120/120 | I28: RO | J28: RO | L28: AEROSTAR S.A. | M28: Unitatea Militara nr. 01969 -Campia Turzii | N28: NATIONAL_AGENCY
A29: c64d8b93-8a1e-4604-960a-e4a55f54544c | B29: 42453 | C29: 42453 | D29: AWARDED | E29: 42453 | G29: 2016 | H29: Splint 3.2x50 DIN94 A2 | I29: RO | J29: RO | L29: AEROSTAR S.A. | M29: Ministerul Apararii Nationale - U.M.01912 BORCEA
A30: 79ea3bf2-06a4-4cc5-9703-da5cea33eb2a | B30: 43614 | C30: 43614 | D30: AWARDED | E30: 43614 | G30: 2019 | H30: Caseta DTC , reper AO 02582A-00 | I30: RO | J30: RO | K30: 1238905 | L30: AEROSTAR | M30: Ministerul Apararii Nationale - U.M.01912 BORCEA | O30: 1238905
A31: ced98527-e805-436b-82b9-65d708f131f6 | B31: 42613 | C31: 42613 | D31: AWARDED | E31: 42613 | G31: 2016 | H31: Conducta flexibila 94-9511-570/A | I31: RO | J31: RO | K31: 131336 | L31: AEROSTAR S.A. | M31: Ministerul Apararii Nationale - U.M.01912 BORCEA | O31: 131336
A32: 4fcd7ca8-d6d6-4a2a-bfec-ac2389629a06 | B32: 42639 | C32: 42639 | D32: AWARDED | E32: 42639 | G32: 2016 | H32: Casca pilot HGU 55/P | I32: RO | J32: RO | K32: -24653 | L32: AEROFINA S.A. | M32: Ministerul Apararii U.M. 02512Z | N32: NATIONAL_AUTHORITY | O32: 1832.7
A33: 2b38aa63-b826-49b0-aa76-280aa1310154 | B33: 43788 | C33: 43788 | D33: AWARDED | E33: 43788 | G33: 2019 | H33: Diafragma 76-5505-592 | I33: RO | J33: RO | K33: -7090 | L33: AEROSTAR | M33: Ministerul Apararii Nationale - U.M.01912 BORCEA | O33: 1880.08
A34: 36adcabd-4e98-4808-9480-744ed4166a7f | B34: 43773 | C34: 43773 | D34: AWARDED | E34: 43773 | G34: 2019 | H34: AX SUSPENSIE S52.64.218 | I34: RO | J34: RO | K34: 651.93 | L34: AEROSTAR | M34: Ministerul Apararii Nationale - U. M. 02015 Bacau | N34: NATIONAL_AUTHORITY | O34: 651.93
A35: 271fee60-c7dc-480e-9a32-139654e6c41d | B35: 42549 | C35: 42549 | D35: AWARDED | E35: 42550 | G35: 2016 | H35: Inel etansare 0257107 | I35: RO | J35: RO | K35: 389.66 | L35: AEROSTAR S.A. | M35: Unitatea Militara nr. 01969 -Campia Turzii | N35: NATIONAL_AGENCY | O35: 389.66
A36: a20fabf1-b8c3-405f-8f69-178d7df64b63 | B36: 41254 | C36: 41254 | D36: AWARDED | E36: 41255 | G36: 2012 | H36: Casca pilot tip HGU-55/P, marca GENTEX, marime medie, culoare gri. | I36: RO | J36: RO | K36: 1775.51 | L36: AEROFINA S.A. | M36: Ministerul Apararii U.M. 02512Z | N36: NATIONAL_AUTHORITY | O36: 1775.51
A37: b0c0d5d7-9ba9-45f7-80c2-6fcad6ffa0a1 | B37: 42345 | C37: 42345 | D37: AWARDED | E37: 42346 | G37: 2015 | H37: Conducta 94-5512-10-56 | I37: RO | J37: RO | K37: 511.9 | L37: AEROSTAR S.A. | M37: Unitatea Militara nr. 01969 -Campia Turzii | N37: NATIONAL_AGENCY | O37: 511.9
A38: ee62be08-8bf2-4292-94cb-9b42220c1581 | B38: 42345 | C38: 42345 | D38: AWARDED | E38: 42346 | G38: 2015 | H38: Garnitura 4327-155N607-33,4-5,4-2 | I38: RO | J38: RO | L38: AEROSTAR S.A. | M38: Unitatea Militara nr. 01969 -Campia Turzii | N38: NATIONAL_AGENCY
A39: d004200e-27d7-4061-9697-2fb911e8d802 | B39: 43893 | C39: 43893 | D39: AWARDED | E39: 43894 | G39: 2020 | H39: Conducte flexibile reper 76-5511-1890-2 94-5511-570A Kit etansare PS 870 B1/2 | I39: RO | J39: RO | K39: 4298.78 | L39: AEROSTAR | M39: Ministerul Apararii Nationale - U.M.01912 BORCEA | O39: 4298.78
A40: dfe7e178-7a8c-4d05-8e5d-ad6ba1beb494 | B40: 42345 | C40: 42345 | D40: AWARDED | E40: 42346 | G40: 2015 | H40: Inel etansare 2262a-222-2 | I40: RO | J40: RO | L40: AEROSTAR S.A. | M40: Unitatea Militara nr. 01969 -Campia Turzii | N40: NATIONAL_AGENCY
...

Sheet Copernicus
A1: Copernicus contracts (> 15 000 euro)
A2: Country | B2: 2014 | C2: 2015 | D2: 2016 | E2: 2017 | F2: 2018 | G2: 2019 | H2: 2020 | I2: 2021 | J2: 2022 | K2: #contracts | L2: % non EU contracts
A3: UK | B3: - | C3: - | D3: - | E3: - | F3: - | G3: - | H3: =COUNTIF('2020'!B2:B155,A3) -> 4 | I3: =COUNTIF('2021'!B2:B224,A3) -> 6 | J3: =COUNTIF('2022'!B2:B334,A3) -> 5 | K3: =SUM(H3:J3) -> 15 | L3: =K3/K9 -> 0.011709602
A4: NO | B4: =COUNTIF('2014'!B:B,Copernicus!A4) -> 1 | C4: =COUNTIF('2015'!B:B,A4) -> 6 | D4: =COUNTIF('2016'!B:B,A4) -> 2 | E4: =COUNTIF('2017'!B:B,A4) -> 1 | F4: =COUNTIF('2018'!B:B,A4) -> 0 | G4: =COUNTIF('2019'!B:B,A4) -> 2 | H4: =COUNTIF('2020'!B:B,A4) -> 1 | I4: =COUNTIF('2021'!B:B,A4) -> 5 | J4: =COUNTIF('2022'!B:B,A4) -> 4 | K4: =SUM(B4:J4) -> 22 | L4: =K4/K9 -> 0.017174083
A5: CH | B5: =COUNTIF('2014'!B:B,A5) -> 0 | C5: =COUNTIF('2015'!B:B,A5) -> 10 | D5: =COUNTIF('2016'!B:B,A5) -> 4 | E5: =COUNTIF('2017'!B:B,A5) -> 3 | F5: =COUNTIF('2018'!B:B,A5) -> 1 | G5: =COUNTIF('2019'!B:B,A5) -> 2 | H5: =COUNTIF('2020'!B:B,A5) -> 0 | I5: =COUNTIF('2021'!B:B,A5) -> 2 | J5: =COUNTIF('2022'!B:B,A5) -> 0 | K5: =SUM(B5:J5) -> 22 | L5: =K5/K9 -> 0.017174083
A6: US | B6: =COUNTIF('2014'!B:B,Copernicus!A6) -> 0 | C6: =COUNTIF('2015'!B:B,Copernicus!A6) -> 1 | D6: =COUNTIF('2016'!B:B,Copernicus!A6) -> 0 | E6: =COUNTIF('2017'!B:B,Copernicus!A6) -> 0 | F6: =COUNTIF('2018'!B:B,Copernicus!A6) -> 0 | G6: =COUNTIF('2019'!B:B,Copernicus!A6) -> 0 | H6: =COUNTIF('2020'!B:B,Copernicus!A6) -> 0 | I6: =COUNTIF('2021'!B:B,Copernicus!A6) -> 0 | J6: =COUNTIF('2022'!B:B,Copernicus!A6) -> 1 | K6: =SUM(B6:J6) -> 2 | L6: =K6/K9 -> 0.0015612802
A7: CA | B7: =COUNTIF('2014'!B:B,Copernicus!A7) -> 0 | C7: =COUNTIF('2015'!B:B,Copernicus!A7) -> 2 | D7: =COUNTIF('2016'!B:B,Copernicus!A7) -> 1 | E7: =COUNTIF('2017'!B:B,Copernicus!A7) -> 1 | F7: =COUNTIF('2018'!B:B,Copernicus!A7) -> 0 | G7: =COUNTIF('2019'!B:B,Copernicus!A7) -> 2 | H7: =COUNTIF('2020'!B:B,Copernicus!A7) -> 1 | I7: =COUNTIF('2021'!B:B,Copernicus!A7) -> 4 | J7: =COUNTIF('2022'!B:B,Copernicus!A7) -> 1 | K7: =SUM(B7:J7) -> 12 | L7: =K7/K9 -> 0.0093676815
A8: Total non EU contracts | B8: =SUM(B4:B7) -> 1 | C8: =SUM(C4:C7) -> 19 | D8: =SUM(D4:D7) -> 7 | E8: =SUM(E4:E7) -> 5 | F8: =SUM(F4:F7) -> 1 | G8: =SUM(G4:G7) -> 6 | H8: =SUM(H3:H7) -> 6 | I8: =SUM(I3:I7) -> 17 | J8: =SUM(J3:J7) -> 11 | K8: =SUM(B8:J8) -> 73 | L8: =K8/K9 -> 0.056986729
A9: Total #contracts | B9: =COUNTA('2014'!B:B)-1 -> 6 | C9: =COUNTA('2015'!B:B)-1 -> 189 | D9: =COUNTA('2016'!B:B)-1 -> 115 | E9: =COUNTA('2017'!B:B)-1 -> 86 | F9: =COUNTA('2018'!B:B)-1 -> 81 | G9: =COUNTA('2019'!B:B)-1 -> 94 | H9: =COUNTA('2020'!B:B)-1 -> 154 | I9: =COUNTA('2021'!B:B)-1 -> 223 | J9: =COUNTA('2022'!B:B)-1 -> 333 | K9: =SUM(B9:J9) -> 1281
A11: Copernicus Sentinels industrial consortium
A12: Country | B12: Sentinel 1 | C12: Sentinel 2 | D12: Sentinel 3 | E12: Sentinel 4 | F12: Sentinel 5 | G12: #components | H12: % non EU components
A13: NO | B13: =COUNTIF('Sentinel 1'!C:C,Copernicus!A13) -> 1 | C13: =COUNTIF('Sentinel 2'!C:C,Copernicus!A13) -> 0 | D13: =COUNTIF('Sentinel 3'!C:C,Copernicus!A13) -> 2 | E13: =COUNTIF('Sentinel 4'!C:C,Copernicus!A13) -> 2 | F13: =COUNTIF('Sentinel 5'!C:C,Copernicus!A13) -> 0 | G13: =SUM(B13:F13) -> 5 | H13: =G13/G19 -> 0.013812155
A14: CH | B14: =COUNTIF('Sentinel 1'!C:C,Copernicus!A14) -> 9 | C14: =COUNTIF('Sentinel 2'!C:C,Copernicus!A14) -> 2 | D14: =COUNTIF('Sentinel 3'!C:C,Copernicus!A14) -> 7 | E14: =COUNTIF('Sentinel 4'!C:C,Copernicus!A14) -> 3 | F14: =COUNTIF('Sentinel 5'!C:C,Copernicus!A14) -> 3 | G14: =SUM(B14:F14) -> 24 | H14: =G14/G19 -> 0.066298343
A15: US | B15: =COUNTIF('Sentinel 1'!C:C,Copernicus!A15) -> 1 | C15: =COUNTIF('Sentinel 2'!C:C,Copernicus!A15) -> 2 | D15: =COUNTIF('Sentinel 3'!C:C,Copernicus!A15) -> 0 | E15: =COUNTIF('Sentinel 4'!C:C,Copernicus!A15) -> 0 | F15: =COUNTIF('Sentinel 5'!C:C,Copernicus!A15) -> 0 | G15: =SUM(B15:F15) -> 3 | H15: =G15/G19 -> 0.0082872928
A16: CA | B16: =COUNTIF('Sentinel 1'!C:C,Copernicus!A16) -> 1 | C16: =COUNTIF('Sentinel 2'!C:C,Copernicus!A16) -> 1 | D16: =COUNTIF('Sentinel 3'!C:C,Copernicus!A16) -> 2 | E16: =COUNTIF('Sentinel 4'!C:C,Copernicus!A16) -> 0 | F16: =COUNTIF('Sentinel 5'!C:C,Copernicus!A16) -> 0 | G16: =SUM(B16:F16) -> 4 | H16: =G16/G19 -> 0.011049724
A17: IL | B17: =COUNTIF('Sentinel 1'!C:C,Copernicus!A17) -> 3 | C17: =COUNTIF('Sentinel 2'!C:C,Copernicus!A17) -> 0 | D17: =COUNTIF('Sentinel 3'!C:C,Copernicus!A17) -> 1 | E17: =COUNTIF('Sentinel 4'!C:C,Copernicus!A17) -> 0 | F17: =COUNTIF('Sentinel 5'!C:C,Copernicus!A17) -> 0 | G17: =SUM(B17:F17) -> 4 | H17: =G17/G19 -> 0.011049724
A18: Total non EU components | B18: =SUM(B13:B17) -> 15 | C18: =SUM(C13:C17) -> 5 | D18: =SUM(D13:D17) -> 12 | E18: =SUM(E13:E17) -> 5 | F18: =SUM(F13:F17) -> 3 | G18: =SUM(B18:F18) -> 40 | H18: =G18/G19 -> 0.11049724
A19: Total #components | B19: =COUNTA('Sentinel 1'!C:C)-1 -> 81 | C19: =COUNTA('Sentinel 2'!C:C)-1 -> 38 | D19: =COUNTA('Sentinel 3'!C:C)-1 -> 136 | E19: =COUNTA('Sentinel 4'!C:C)-1 -> 57 | F19: =COUNTA('Sentinel 5'!C:C)-1 -> 50 | G19: =SUM(B19:F19) -> 362

Sheet Sentinel 1
A1: Component | B1: Supplier | C1: Country
A2: GPS | B2: RUAG (Austria) | C2: AT
A3: TCS | B3: RUAG (Austria) | C3: AT
A4: PCDU | B4: TAS-Etca (Belgium) | C4: BE
A5: Basic products | B5: MDA (Canada) | C5: CA
A6: STR | B6: RUAG (Switzerland) | C6: CH
A7: STR | B7: Apco (Switzerland) | C7: CH
A8: End-to-end SAR system calibration | B8: DLR (Germany) | C8: DE
A9: FSS | B9: Jena-Optronik (Germany) | C9: DE
A10: RW | B10: Rockwell C (Germany) | C10: DE
A11: SAW | B11: Astrium (Germany) | C11: DE
A12: PVF | B12: Astrium (Germany) | C12: DE
... A82: Test equipment | B82: SSBV (Netherlands) | C82: NL

Sheet Sentinel 2
A1: Component | B1: Supplier | C1: Country
A2: GPS receiver | B2: RUAG (Austria) | C2: AT
A3: Electrical Ground Support Equipment (EGSE) | B3: Siemens (Austria) | C3: AT
A4: Mirror polishing | B4: AMSO (Belgium) | C4: BE
A5: MGSE | B5: Sermati (Canada) | C5: CA
A6: Solar Array Drive Mechanism | B6: RUAG (Switzerland) | C6: CH
A7: Mechanical Ground Support Equipment (MGSE) for the instrument primary and secondary structure and the satellites | B7: APCO (Switzerland), | C7: CH
A8: Satellites Platform procurement and AIT, mass memory, Coarse Earth and Sun Sensors, propulsion | B8: Prime Contractor: Astrium GmbH (Germany) | C8: DE
A9: Star sensors, Video and Compression Unit, optical filters | B9: Jena-Optronik (Germany) | C9: DE
A10: Star sensors, Video and Compression Unit, optical filters | B10: Optics Balzers Jena (Germany) | C10: DE
A11: Magnetometers and magnetorquers | B11: ZARM (Germany) | C11: DE
A12: Mechanical Ground Support Equipment (MGSE) for the instrument primary and secondary structure and the satellites | B12: Xperion (Germany) | C12: DE
... A39: Miniature Inertial Measurement Unit | B39: Honeywell (USA) | C39: US

Sheet Sentinel 3
A1: Component | B1: Supplier | C1: Country
A2: MGSE | B2: AMOS (Belgium) | C2: BE
A3: AOCS engineering support | B3: NCG (Canada) | C3: CA
A4: O-SPS scene generator | B4: Vista (Germany) | C4: DE
A5: PA software | B5: ETIQ (Germany) | C5: DE
A6: Mission analysis | B6: Deimos (Spain) | C6: ES
A7: Support to PA activities | B7: Alter (Spain) | C7: ES
A8: Support to PA activities | B8: Thales Alenia Space España (Spain) | C8: ES
A9: CPPA | B9: Alter (Spain) | C9: ES
A10: O-GPP | B10: Deimos (Spain) | C10: ES
A11: SRAL GPP | B11: Isardsat (Spain) | C11: ES
A12: GPS GPP & SPS | B12: GMV (Spain) | C12: ES
... A25: AOCS SCOE | B25: Studiel UK (UK) | C25: UK
A26: Schedule/documentation/configuration | B26: VEGA
A27: Platform Prime Contractor/System Engineering Support | B27: Thales Alenia Space (Italy) | C27: IT
A28: Battery | B28: ABSL (UK) | C28: UK
A29: PDHU | B29: Astrium GmbH (Germany) | C29: DE
A30: PCDU | B30: Thales Alenia Space ETCA (Belgium) | C30: BE
A31: Structure | B31: RUAG (Switzerland) | C31: CH
A32: TXA | B32: Thales Alenia Space España (Spain) | C32: ES
A33: SBT | B33: Thales Alenia Space España (Spain) | C33: ES
A34: Thermal control | B34: EADS Casa Espacio (Spain) | C34: ES
A35: SADM | B35: Kongsberg (Norway) | C35: NO
A36: Solar Array Wings | B36: Thales Alenia Space (France) | C36: FR
A37: SBA | B37: RUAG (Sweden) | C37: SW
A38: XBAA | B38: Thales Alenia Space (Italy) | C38: IT
... A138: VCF VEM Support to validation | B138: Skysoft (Portugal) | C138: PT

Sheet Sentinel 4
A1: Component | B1: Supplier | C1: Country
A2: (AIT) OGSE | B2: MICOS | C2: CH
A3: (AIT) OGSE | B3: Optek | C3: IT
A4: (AIT) OGSE | B4: NPL | C4: UK
A5: Aperature Cover | B5: RUAG | C5: AT
A6: Aperature Cover | B6: Active Space | C6: PT
A7: Beam Splitter Assy. | B7: JOP | C7: DE
A8: Beam Splitter Assy. | B8: IOF | C8: DE
A9: Beam Splitter Assy. | B9: Sagem | C9: FR
A10: C&C Facilities | B10: STFC | C10: UK
A11: C&C Facilities | B11: RAL | C11: UK
A12: C&C OGSE | B12: UCLC | C12: UK
... A58: UV/VIS Spectrometer Optics Assy. | B58: JOP | C58: DE

Sheet Sentinel 5
A1: Component | B1: Supplier | C1: Country
A2: IOMT | B2: RUAG | C2: AT
A3: EGSE | B3: ATOS | C3: AT
A4: C&C OGSE SM, test support, E2E verification | B4: CSL | C4: BE
A5: Structure | B5: Almatech | C5: CH
A6: CAS | B6: Micos | C6: CH
A7: MGSE | B7: APCO | C7: CH
A8: Prime contractor | B8: Airbus Defence and Space GMBH | C8: DE
A9: CFRP panels | B9: Xperion | C9: DE
A10: Heat pipes | B10: Airbus DS GMBH | C10: DE
A11: Mechanical engineering & mech. MAIT | B11: STI | C11: DE
A12: NIR SO | B12: Jena Optronik | C12: DE
... A51: C&C Test facilities | B51: RAL | C51: UK

Sheet 2014
A1: Name of Recipient | B1: Country | C1: Summary of Activities | D1: Contract value
A2: ARIANESPACE S. A. | B2: FR | C2: PROVISION OF THE LAUNCH SERVICES FOR THE SENTINEL-2 PAYLOAD | D2: 6,825,700.00
A3: EUROCKOT LAUNCH SERVICES GMBH | B3: DE | C3: PROVISION OF THE LAUNCH SERVICES FOR THE SENTINEL-5P PAYLOAD | D3: 26,900,000.00
A4: e-GEOS SPA | B4: IT | C4: PREPARATION AND OPERATION OF THE CORE X-BAND ACQUISITION AND NEAR REAL-TIME FACILITIES FOR THE COPERNICUS SENTINEL SATELLITES: MATERA GROUND STATION | D4: 13,378,925.00
A5: KONGSBERG SATELLITE SERVICES AS (KSAT) | B5: NO | C5: PREPARATION AND OPERATION OF THE CORE X-BAND ACQUISITION AND NEAR REAL-TIME FACILITIES FOR THE COPERNICUS SENTINEL SATELLITES: SVALBARD GROUND STATION | D5: 43,662,184.00
A6: Collecte Localisation Satellites (CLS) | B6: FR | C6: MISSION PERFORMANCE CENTERS (MPC) FOR SENTINEL 1A/B. MPCs are responsible for calibration, validation, quality control and end-to-end system performance assessment. The MPCs include expert teams for specific cal/val, off-line quality control and algorithm correction activities. | D6: 6,473,009.00
A7: T-SYSTEMS INTERNATIONAL GMBH | B7: DE | C7: DATA CIRCULATION & DISSEMINATION FOR THE WIDE AREA NETWORK (WAN) AND SECURITY SERVICES FOR THE COPERNICUS SENTINELS SATELLITES | D7: 16,072,707.21

Sheet 2015
A1: Name of Recipient | B1: Country | C1: Summary of Activities | D1: • Copernicus 2015
A2: ABSL SPACE PRODUCTS | B2: UK | C2: {Sentinel 1 Satellites C/D IJnits construction | D2: 3,038,000.00
A3: ABSL SPACE PRODUCTS | B3: UK | C3: Sentinel 2 Satellites C/D Units construction | D3: 997,000.00
A4: ABSL SPACE PRODUCTS | B4: UK | C4: (Sentinel 3 Satellite C/D Units Construction | D4: 1,049,735.00
A5: ACM-ST S.A.S. | B5: FR | C5: MISSION PERFORMANCE CENTERS (MPC) FOR SENTINELS. MPCs are responsible for calibration, :validation, quality control and end-to-end system performance assessment. The MPCs include expert teams for specific cal/val, off-line quality control and algorithm correction activities. | D5: 21,882,062.00
A6: ACRI-ST S.A.S. | B6: FR | C6: Preparations and operations of the off-line Processing and Archiving Centres for sentinel {satellites | D6: 7,745,656.00
A7: ACRI-ST S.A.S. | B7: FR | C7: (Sentinel 3 Payload Data Ground Segment (PDGS) system operations, maintenance and evolutions | D7: 24,513.00
A8: ACS ADVANCED COMPUTER SYSTEMS | B8: IT | C8: Sentinel 2 Payload Data Ground Segment (PDGS) system operations, maintenance and evolutions | D8: 229,145.00
A9: ADMATIS LTD | B9: HU | C9: 'Sentinel 2 Satellites C/D Units construction | D9: 609,810.00
A10: ADVANCED COMPUTER SYSTEMS SPA | B10: IT | C10: (Sentinel 3 Payload Data Ground Segment (PDGS) system operations, maintenance and evolutions | D10: 71,455.00
A11: AIM INFRAROT-MODULE GMBH | B11: DE | C11: Sentinel 3 Satellite C/D Units Construction | D11: 1,815,000.00
A12: AIRBUS OEFENCE SPACE NETHERLANDS | B12: NL | C12: Sentinel 1 Satellites C/D Units construction | D12: 5,750,000.00
... A35: ARE-SYS SRL | B35: IT | C35: {Sentinel 1B Phase E Activities | D35: 31,800.00
A36: ARIANESPACE | B36: FR | D36: 70,356,152.05
A37: ASTRIUM GMBH - SATELLITES | B37: DE | C37: DATA RELAY SERVICES FOR COPERNICUS SENTINELS (EDRS) | D37: 70,492,472.00
A38: ASTRIUV GMBH - SATELLITES | B38: DE | C38: (Sentinel 1 Satellites C/D Units construction | D38: 76,393,104.00
A39: ASTRIUV GMBH - SATELLITES | B39: DE | C39: Sentinel 1B Phase E Activities | D39: 546,8.89.00
A40: ASTRIUM GMBH - SATELLITES | B40: DE | C40: {Sentinel 2 Satellites C/D Units construction | D40: 101,702,188.00
A41: ASTRIUM GMBH - SATELLITES | B41: DE | C41: •Sentinel 2A Phase E Activities | D41: 6,388,000.00
A42: ASTRIUM GMBH - SATELLITES | B42: DE | C42: •Sentinel 3 Satellite C/D Units Construction | D42: 6,471,809.00
A43: ASTRIUM GMBH - SATELLITES | B43: DE | C43: Sentinel 5 Satellites- Recurrent Models B and C | D43: 81,261,548.00
A44: ASTRIUM GMBH - SATELLITES | B44: DE | C44: Sentinel 6B Satellite Instrument Construction | D44: 4,061,579.00
A45: AXON KABELGMBH | B45: DE | C45: •Sentinel 1 Satellites C/D Units construction | D45: 250,000.00
A46: Black8ridge AG | B46: DE | C46: •Copernicus Space Component - Data Warehouse activities | D46: 6,867,262.00
A47: BLU ELECTRONIC SRO | B47: IT | C47: Sentinel 1 Satellites C/D Units construction | D47: 800,000.00
A48: BOOSTEC | B48: FR | C48: {Sentinel 2 Satellites C/D Units construction | D48: 2,745,000.00
... A61: DA-DESIGN OY | B61: FI | C61: •Sentinel 1 Satellites C/D Units construction | D61: 4,100,000.00
A62: OEIMOS ENGENHARIA S.A. | B62: PT | D62: 108,040.00
A63: DEMOS IMAGING S.L.U. | B63: ES | C63: Copernicus Space Compon ent - Data Warehouse activities | D63: 18,969,686.00
